Workbook

Sheet 仿真
A1: 序号 | B1: 语料 | C1: 字符长度 | D1: url | E1: 时间 | F1: 地点 | G1: 食品名称 | H1: 涉及企业 | I1: 卫生状况
A2: 1 | B2: 2022年08月29日，在杭州市滨江区，锦绣前程大酒店生产的剁椒拌饭被发现环境卫生不整洁_操作台脏乱_物品摆放混乱无序_垃圾桶未加盖。 | C2: 67 | D2: http://xiuyingmin.com/ | E2: 2022年08月29日 | F2: 杭州市滨江区 | G2: 剁椒拌饭 | H2: 锦绣前程大酒店 | I2: 环境卫生不整洁_操作台脏乱_物品摆放混乱无序_垃圾桶未加盖
A3: 2 | B3: 2023年03月16日，在瓜州县，钱李养殖场生产的藏式腊八粥被发现烂纸箱装塑料杯和塑封贴_发黑发软的水果_有蝇虫。 | C3: 57 | D3: http://tao.cn/ | E3: 2023年03月16日 | F3: 瓜州县 | G3: 藏式腊八粥 | H3: 钱李养殖场 | I3: 烂纸箱装塑料杯和塑封贴_发黑发软的水果_有蝇虫
A4: 3 | B4: 2022年12月11日，在台州市界牌菜场，谷酒小作坊生产的鸡腿_生肉被发现后厨加工场所卫生差_油污积渍重。 | C4: 53 | D4: https://yanghan.cn/ | E4: 2022年12月11日 | F4: 台州市界牌菜场 | G4: 鸡腿_生肉 | H4: 谷酒小作坊 | I4: 后厨加工场所卫生差_油污积渍重
A5: 4 | B5: 2022年02月22日，在钤山西路，燕子坪餐饮店生产的麻辣烫被发现后厨卫生脏乱差。 | C5: 41 | D5: http://www.chaoxia.cn/ | E5: 2022年02月22日 | F5: 钤山西路 | G5: 麻辣烫 | H5: 燕子坪餐饮店 | I5: 后厨卫生脏乱差
A6: 5 | B6: 2022年03月19日，在江苏江阴，江左尚白餐饮有限公司生产的牛肉面被发现后厨环境卫生较差_油污严重_垃圾桶未加盖。 | C6: 58 | D6: https://minxiuying.com/ | E6: 2022年03月19日 | F6: 江苏江阴 | G6: 牛肉面 | H6: 江左尚白餐饮有限公司 | I6: 后厨环境卫生较差_油污严重_垃圾桶未加盖
A7: 6 | B7: 2020年03月16日，在凤冈县天桥镇，沙县营养小吃生产的沙丁鱼被发现后厨卫生太差_物品乱摆乱放。 | C7: 49 | D7: http://www.panwei.cn/ | E7: 2020年03月16日 | F7: 凤冈县天桥镇 | G7: 沙丁鱼 | H7: 沙县营养小吃 | I7: 后厨卫生太差_物品乱摆乱放
A8: 7 | B8: 2022年01月20日，在南涧镇中兴路，景东回族牛肉馆生产的汉堡被发现餐用具摆放混乱_后厨油污严重。 | C8: 50 | D8: http://68.cn/ | E8: 2022年01月20日 | F8: 南涧镇中兴路 | G8: 汉堡 | H8: 景东回族牛肉馆 | I8: 餐用具摆放混乱_后厨油污严重
A9: 8 | B9: 2021年11月27日，在萧山区城厢街道，阿彪排档生产的蟹_土豆_猪蹄和牛骨_鸡爪被发现裱花专间堆放大量外包装等杂物_地面、橱柜，冷藏柜存在大量霉斑_冰柜内半成品原料未密闭存放。 | C9: 89 | D9: https://ol.cn/ | E9: 2021年11月27日 | F9: 萧山区城厢街道 | G9: 蟹_土豆_猪蹄和牛骨_鸡爪 | H9: 阿彪排档 | I9: 裱花专间堆放大量外包装等杂物_地面、橱柜，冷藏柜存在大量霉斑_冰柜内半成品原料未密闭存放
A10: 9 | B10: 2021年02月10日，在铁岭街35号，七里香小吃店生产的凉菜被发现厨房整体脏乱_消毒柜未规范使用_操作台物品摆放杂乱_烹饪区油污严重。 | C10: 68 | D10: http://www.qiangguiying.cn/ | E10: 2021年02月10日 | F10: 铁岭街35号 | G10: 凉菜 | H10: 七里香小吃店 | I10: 厨房整体脏乱_消毒柜未规范使用_操作台物品摆放杂乱_烹饪区油污严重
A11: 10 | B11: 2020年08月30日，在河北省龙堌镇，玖玖玖豆花面生产的奶茶被发现食材未离地离墙摆放。 | C11: 44 | D11: https://guiying.cn/ | E11: 2020年08月30日 | F11: 河北省龙堌镇 | G11: 奶茶 | H11: 玖玖玖豆花面 | I11: 食材未离地离墙摆放
A12: 11 | B12: 2023年08月01日，在弥渡县，正新鸡排生产的干锅被发现后厨三防设施不到位_冰柜内未及时除霜、食材裸露存放。 | C12: 55 | D12: http://www.pl.cn/ | E12: 2023年08月01日 | F12: 弥渡县 | G12: 干锅 | H12: 正新鸡排 | I12: 后厨三防设施不到位_冰柜内未及时除霜、食材裸露存放
A13: 12 | B13: 2020年01月25日，在黄石港区，龙港市小剑饭店生产的叉烧饭被发现食品与有毒有害物质混放_食品未离地离墙。 | C13: 54 | D13: https://www.gp.cn/ | E13: 2020年01月25日 | F13: 黄石港区 | G13: 叉烧饭 | H13: 龙港市小剑饭店 | I13: 食品与有毒有害物质混放_食品未离地离墙
... A601: 600 | B601: 2023年11月27日，在浙江省平湖市广中北路，蜗牛花甲生产的炒虾被发现环境卫生脏乱差_苍蝇蚊虫横飞_房梁角落大量蜘蛛网。 | C601: 61 | D601: http://www.deng.cn/ | E601: 2023年11月27日 | F601: 浙江省平湖市广中北路 | G601: 炒虾 | H601: 蜗牛花甲 | I601: 环境卫生脏乱差_苍蝇蚊虫横飞_房梁角落大量蜘蛛网

Sheet Sheet1
A1: 序号 | B1: 语料 | C1: 字符长度 | D1: url | E1: 时间 | F1: 地点 | G1: 食品名称 | H1: 涉及企业 | I1: 卫生状况
A2: 1 | B2: 5月11日，江西省宜春市一名大货车司机在宜丰县海峰食品厂拉货，发现该厂卤蛋生产车间卫生堪忧，生存作坊又脏又乱，还养鸡、鸭、鹅到处跑，生产车间一股恶臭， | C2: 75 | D2: https://www.toutiao.com/article/7231834493609787956/?channel=&source=news | E2: 5月11日 | F2: 江西省宜春市 | G2: 卤蛋 | H2: 宜丰县海峰食品厂 | I2: 又脏又乱_鸡、鸭、鹅到处跑_恶臭
A3: 2 | B3: 7月17日，有博主曝光了一则华莱士后厨的卧底视频，工作人员徒手制作炸鸡、汉堡；鸡块掉在地上放回锅里重新炸；清洗抽烟烟机，洗剂直接滴进油锅里滋滋作响。 | C3: =LEN(B3) -> 74 | D3: https://baijiahao.baidu.com/s?id=1705766714671444434&wfr=spider&for=pc | E3: 7月11日 | G3: 炸鸡、汉堡_鸡块 | H3: 华莱士 | I3: 徒手制作炸鸡、汉堡_鸡块掉在地上_洗剂直接滴进油锅里
A4: 3 | B4: 盘点华莱士出过的丑闻。 早在2019年“315”的时候，就有媒体曝光过华莱士后厨的“脏乱差”。比如，鸡翅掉在地上继续卖；蟑螂遍地跑 汉堡过期继续卖； | C4: =LEN(B4) -> 74 | D4: https://baijiahao.baidu.com/s?id=1705766714671444434&wfr=spider&for=pc | E4: 2019年3月15日 | G4: 鸡翅_汉堡 | H4: 华莱士 | I4: 鸡翅掉在地上继续卖_蟑螂遍地跑_汉堡过期继续卖
A5: 4 | B5: 8月17日，福州市的市场监管人员突击检查了一家名为“叫了只炸鸡”的网红炸鸡店 到处都是遍地随意堆放的食材，没有清理的蜘蛛网，甚至在不少地方还见到了老鼠粪便。 | C5: =LEN(B5) -> 80 | D5: https://baijiahao.baidu.com/s?id=1708430547324620744&wfr=spider&for=pc | E5: 8月17日 | F5: 福州市 | G5: 炸鸡 | H5: 叫了只炸鸡 | I5: 随意堆放食材_没有清理的蜘蛛网_老鼠粪便
A6: 5 | B6: 7月29日，记者发布了杨国福麻辣烫存在卫生问题的视频。你很难想象老鼠、蟑螂混住的地方，会是杨国福的后厨！你吃的芝麻酱是老鼠吃过的；你吃的蔬菜，是刷鞋池里洗的。 | C6: =LEN(B6) -> 79 | D6: https://weibo.com/2328665481/Kr0tTaTJA | E6: 7月29日 | G6: 麻辣烫 | H6: 杨国福 | I6: 老鼠、蟑螂混住_芝麻酱老鼠吃过_刷鞋池里洗蔬菜
A7: 6 | B7: 1月26日晚，夏老板请公司员工吃年夜饭。 一位员工吃到了鸡大便。把炸鸡掰开，一大截鸡大便从鸡腰处直到鸡肛门。他当即带着员工来到位于临平的沃尔玛超市讨说法。 | C7: =LEN(B7) -> 79 | D7: http://www.linkshop.com/web/Article_news.aspx?ArticleId=153405 | E7: 1月26日 | F7: 临平 | G7: 炸鸡 | H7: 沃尔玛 | I7: 鸡大便
A8: 7 | B8: 2022年1月20日四川省眉山市市场监管局对一家名为“叫了个炸鸡”的外卖店开展检查。该店存在用垃圾袋装食品、用生锈的剪刀剪鸡腿、生肉不覆膜放冰柜等违规行为。 | C8: =LEN(B8) -> 78 | D8: https://m.thepaper.cn/baijiahao_16402940 | E8: 2022年1月20日 | F8: 四川省眉州市 | G8: 鸡腿_生肉 | H8: 叫了个炸鸡 | I8: 垃圾袋装食品_生锈的剪刀剪鸡腿_生肉不覆膜放冰柜
A9: 8 | B9: 锅三侠麻辣香锅，位于杭州市余杭区海创科技园地下美食城，是今年10月1日新开业的，后厨的环境很差，白菜花菜等菜品从来不洗，油反复用，米饭吃不完第二天继续给客人吃。 | C9: =LEN(B9) -> 80 | D9: https://baijiahao.baidu.com/s?id=1717934950067151163&wfr=spider&for=pc | E9: 10月1日 | F9: 杭州市余杭区 | G9: 麻辣香锅 | H9: 锅三侠 | I9: 后厨的环境差_菜品从来不洗_油反复用_米饭第二天继续给客人吃
A10: 9 | B10: 1月31日，在南通市区狼山便民疏导点里的一家麻辣香锅店卫生堪忧。店内共有两人配菜、烹煮、打包都挤在一间屋子里。由于没有通风口，里面臭气熏天。 | C10: =LEN(B10) -> 70 | D10: https://m.163.com/dy/article/D9GDRKDN0514EGPO.html | E10: 1月31日 | F10: 南通市 | G10: 麻辣香锅 | I10: 臭气熏天
A11: 10 | B11: 4月23日讯，执法人员对铁岭街35号的金城烧烤店进行了检查，后厨在案板上放着客人吃剩下的麻辣汤料、肉串等。满是污泥的地面上放置着大量没有经过刷洗的竹签子。 | C11: =LEN(B11) -> 77 | D11: https://heilongjiang.dbw.cn/system/2013/04/23/054724366.shtml | E11: 2018年4月23日 | F11: 铁岭街35号 | G11: 烧烤 | H11: 金城烧烤店 | I11: 案板上放着客人吃剩下的麻辣汤料、肉串_地面污泥_放置没有经过刷洗的竹签子
A12: 11 | B12: 2019年，徐州新沂市,一家"凯瑞麻辣香锅"，加工麻辣香锅的后厨环境脏乱不堪：墙壁黢黑、灶台油腻、各类食材随意堆放，天花板上还挂满了蜘蛛网。 | C12: =LEN(B12) -> 71 | D12: http://news.jstv.com/a/20190516/1558054956308.shtml | E12: 2019年 | F12: 徐州新沂市 | G12: 麻辣香锅 | H12: 凯瑞麻辣香锅 | I12: 后厨环境脏乱_墙壁黢黑_灶台油腻_食材随意堆放_天花板挂满了蜘蛛网
A13: 12 | B13: 2016年4月22日，无锡市“杨铭宇”黄焖鸡，用的是口感不佳的进口冻肉，加工地点在偏僻的废弃工厂。现场脏乱不堪，工人没有佩戴任何隔离工具，砧板已发霉。 | C13: =LEN(B13) -> 75 | D13: https://mp.weixin.qq.com/s?__biz=MzA4MzcyMTQ5Nw==&mid=2653693376&idx=3&sn=66ce67ec940158ed26d4a5445b9bdbc5&chksm=842aa9b6b35d20a0b760739c6c602af7d7de2776946dd33a837a207313ea91ebb706b738d847&scene=27 | E13: 2016年4月22日 | F13: 无锡市 | G13: 黄焖鸡 | H13: 杨铭宇 | I13: 用进口冻肉_现场脏乱_工人没有隔离工具_砧板发霉
A14: 13 | B14: 江苏江阴的一家黄焖鸡交货小作坊被本地安全部破获。 2020年4月17安全部对这个小作坊作出了查验,发觉自然环境脏乱差,生产加工职工乃至没有穿工作服装,戴手套。 | C14: =LEN(B14) -> 79 | D14: http://zgmuyw.com/xinwen/2238.html | E14: 2020年4月17日 | F14: 江苏江阴 | G14: 黄焖鸡 | I14: 环境脏乱差_工人没穿工服和手套
A15: 14 | B15: 3月15日曝光的插旗菜业，是湖南省华容县较大的蔬菜再加工企业，在收土坑酸菜的地方，工人要么穿着拖鞋，要么光着脚，在酸菜上踩来踩去。抽完的烟头直接扔到酸菜上。 | C15: =LEN(B15) -> 78 | D15: https://m.thepaper.cn/baijiahao_17141260 | E15: 3月15日 | F15: 湖南省华容县 | G15: 酸菜 | H15: 插旗菜业 | I15: 工人在酸菜上踩来踩去_烟头扔酸菜上
A16: 15 | B16: 3月31日，在安徽亳州，有网友爆料称，某酸菜咸菜生产作坊环境较脏，池子里面都是污垢，就连装货的铲车铲子上面都是粪便，引起广泛关注。 | C16: =LEN(B16) -> 67 | D16: https://www.zhihu.com/question/592993617/answer/2969383839?utm_id=0 | E16: 3月13日 | F16: 安徽亳州 | G16: 酸菜_咸菜 | I16: 环境较脏_池子里面污垢_铲车上面粪便
A17: 16 | B17: 据自贡市市场监督管理局7月22日消息，董小姐烤肉饭，现场环境脏、乱、差，物品堆放混乱，厨房油污较重。 | C17: =LEN(B17) -> 50 | D17: https://www.sohu.com/a/479200013_121123883 | E17: 7月22日 | F17: 自贡市 | G17: 烤肉饭 | H17: 董小姐 | I17: 环境脏、乱、差_物品堆放混乱_厨房油污较重
A18: 17 | B18: 7月22日自贡小辣椒盐帮土菜馆,冰箱内生、熟食品混放,易交叉污染；环境卫生脏、乱、差：厨房油污较重，风扇、灭蝇灯上积尘较多，有苍蝇 | C18: =LEN(B18) -> 65 | D18: https://www.sohu.com/a/479200013_121123883 | E18: 2021年7月22日 | F18: 自贡 | H18: 小辣椒盐帮土菜馆 | I18: 交叉污染_环境脏乱差_厨房油污较重_积尘较多_有苍蝇
A19: 18 | B19: 2021年11月26日走进门就看到了满店的油污和血迹。原来这是一家专门做火锅类产品的店，成都市场监管执法人员找到了他们的冷藏柜结果刚打开冷藏柜就闻到了一股恶臭。 | C19: =LEN(B19) -> 80 | D19: https://baijiahao.baidu.com/s?id=1717382090347237958&wfr=spider&for=pc | E19: 2021年11月26日 | F19: 成都 | G19: 火锅 | I19: 油污_血迹_恶臭
A20: 19 | B20: 2022年1月17日一家处于安徽合肥的速食包生产厂家生产的速食包基本上全部用变质肉，卖给外卖商家。工作人员从满是血水的池子里捞排骨粒无一例外全部颜色发白。 | C20: =LEN(B20) -> 79 | D20: https://baijiahao.baidu.com/s?id=1722095888461392546&wfr=spider&for=pc | E20: 2022年1月17日 | F20: 安徽合肥 | G20: 速食包 | I20: 用变质肉_血水池捞排骨粒_排骨粒颜色发白
A21: 20 | B21: 2018年10月21日拍客曝光一家叫做三米粥铺的后厨极其脏乱，粥桶随地乱放，砧板生熟不分且有其他事物残留，小米糕已经发霉长满黑点，炸物使用油颜色已成深色。 | C21: =LEN(B21) -> 77 | D21: https://www.jksb.com.cn/html/supervision/consumer/2018/1021/129874.html | E21: 2018年10月21日 | G21: 粥_小米糕_炸物 | H21: 三米粥铺 | I21: 后厨脏乱_粥桶乱放_砧板生熟不分有残留_
A22: 21 | B22: 2021年08月23日报使用过期食材和隔夜死蟹已经成为北京胖哥俩肉蟹煲的惯例。比如将隔夜的死蟹充当活蟹卖；使用腐烂的土豆、变质的猪蹄和牛骨。 | C22: =LEN(B22) -> 70 | D22: https://baijiahao.baidu.com/s?id=1708860863721011161&wfr=spider&for=pc | E22: 2021年08月23日 | F22: 北京 | G22: 蟹_土豆_猪蹄和牛骨_鸡爪 | H22: 胖哥俩肉蟹煲 | I22: 死蟹充当活蟹_使用腐烂的土豆、变质的猪蹄和牛骨
A23: 22 | B23: 据四川观察报道，2023年9月21日，深圳有家长检查学校配餐公司配置的预制菜，发现环境恶劣，器具发霉，肉散落一地。 | C23: =LEN(B23) -> 58 | D23: https://baijiahao.baidu.com/s?id=1777631313710140484&wfr=spider&for=pc | E23: 2023年9月21日 | F23: 深圳 | G23: 预制菜 | H23: 学校配餐公司 | I23: 环境恶劣_器具发霉_肉散落一地
A24: 23 | B24: 2021年8月16日，台江区林世钦快餐店,发现当事人店内后厨卫生较差，食品原料落地摆放、垃圾桶未加盖、员工无健康证、多名员工未佩戴口罩。 | C24: =LEN(B24) -> 68 | D24: https://baijiahao.baidu.com/s?id=1715320277834267848&wfr=spider&for=pc | E24: 2021年8月16日 | F24: 台江区 | G24: 快餐 | H24: 林世钦快餐店 | I24: 后厨卫生较差_食品原料落地摆放_垃圾桶未加盖
A25: 24 | B25: 2021年8月3日，福州市晋安区燕子坪餐饮店检查发现当事人店内快餐加工区域，现场有苍蝇；原料和成品存放不规范，存在交叉污染；后厨卫生脏乱差； | C25: =LEN(B25) -> 70 | D25: https://baijiahao.baidu.com/s?id=1715320277834267848&wfr=spider&for=pc | E25: 2021年8月3日 | F25: 福州市晋安区 | G25: 快餐 | H25: 燕子坪餐饮店 | I25: 有苍蝇_原料和成品存放不规范_交叉污染_卫生脏乱差
A26: 25 | B26: 2021年3月13日，北京海淀某“网红”奶茶店用烂纸箱装一次性塑料杯和塑封贴，用发黑发软的水果制作饮品,有蝇虫从塑料杯上爬过后，店员直接用这些杯子装奶茶 | C26: =LEN(B26) -> 76 | D26: https://m.thepaper.cn/baijiahao_17847070 | E26: 2021年3月13日 | F26: 北京海淀 | G26: 奶茶 | H26: “网红”奶茶店 | I26: 烂纸箱装塑料杯和塑封贴_发黑发软的水果_有蝇虫
A27: 26 | B27: 2020年5月11日太原一家自助餐厅,老板要求将当天客人未吃完的肉、菜等重新加工，第二天再上架,哪怕肉已经变质发酸，甚至表面已经变黏稠 | C27: =LEN(B27) -> 67 | D27: https://m.thepaper.cn/baijiahao_17847070 | E27: 2020年5月11日 | F27: 太原 | G27: 肉 | H27: 自助餐厅 | I27: 变质发酸_表面已经变黏稠
A28: 27 | B28: 2022年9月28日庆元县冬林小吃店，制作快餐操作台脏乱差、冰柜物品摆放杂乱，厨房环境卫生不整洁，污水四溅，垃圾桶未加盖 | C28: =LEN(B28) -> 60 | D28: https://mp.weixin.qq.com/s?__biz=MjM5NzM3MTk1Mw==&mid=2652609089&idx=3&sn=e680ffdcb8a088a00065db047bbc6dc8&chksm=bd34331f8a43ba093a785049037fecd0b03fb8f8682f734b112f43c94547266be042d5a190e7&scene=27 | E28: 2022年9月28日 | F28: 庆元县 | G28: 快餐 | H28: 冬林小吃店 | I28: 脏乱差_物品摆放杂乱_卫生不整洁_污水四溅_垃圾桶未加盖
A29: 28 | B29: 2021年8月23日工作人员对东昌府区东昌东路“运河黑牛”餐馆进行检查,该店快餐厨房卫生脏乱差的程度严重,食用油未封闭；厨房垃圾桶脏。 | C29: =LEN(B29) -> 67 | D29: https://baijiahao.baidu.com/s?id=1708886290770240324&wfr=spider&for=pc | E29: 2021年8月23日 | F29: 东昌府区东昌东路 | G29: 快餐 | H29: “运河黑牛”餐馆 | I29: 厨房卫生脏乱差_食用油未封闭_垃圾桶脏
A30: 29 | B30: 2022年7月20日无锡市梁溪区一外卖餐厅快餐操作间里的垃圾桶堆满了垃圾，并裸露在外，地面上污水遍地。这样的照片被一名骑手在第一时间发送至外卖骑手联络群中。 | C30: =LEN(B30) -> 78 | D30: https://www.sohu.com/a/672811795_121687424 | E30: 2022年7月20日 | F30: 无锡市梁溪区 | G30: 快餐 | H30: 外卖餐厅 | I30: 垃圾桶堆满垃圾_地面污水遍地
A31: 30 | B31: 2012年9月20日长沙理工大学金盆岭校区的衡阳米粉店，蛋壳等各种废弃餐厨垃圾直接丢在地上，洗碗、洗拖把共用一个水龙头、一个池子。 | C31: =LEN(B31) -> 65 | D31: https://hunan.sina.com.cn/news/m/2012-09-20/114417472.html | E31: 2012年9月20日 | F31: 长沙理工大学金盆岭校区 | G31: 米粉 | H31: 衡阳米粉店 | I31: 废弃餐厨垃圾直接丢在地上_洗碗、洗拖把共用一个水龙头、一个池子
A32: 31 | B32: 2021年10月12日，位于凤冈县龙泉街道开发区满口香包子铺，三防”设施不到位，店内环境卫生差，苍蝇乱飞，从业人员健康证过期未及时办理。 | C32: =LEN(B32) -> 68 | D32: http://www.gzfenggang.gov.cn/jgsz/zfbm/scjgj/zfxxgk/fdzdgknr/spaq/202110/t20211014_70889734.html | E32: 2021年10月12日 | F32: 凤冈县龙泉街道开发区 | G32: 包子 | H32: 满口香包子铺 | I32: 环境卫生差_苍蝇乱飞
A33: 32 | B33: 2021年10月21日，胖孃豆花面肠旺粉，位于凤冈县龙泉街道女人街，从业人员操作时未穿戴整洁的衣帽、未配戴口罩，店内环境卫生差，地面有白色垃圾。 | C33: =LEN(B33) -> 72 | D33: http://www.gzfenggang.gov.cn/jgsz/zfbm/scjgj/zfxxgk/fdzdgknr/spaq/202110/t20211014_70889734.html | E33: 2021年10月12日， | F33: 凤冈县龙泉街道女人街 | G33: 豆花_ | H33: 胖孃豆花面肠旺粉 | I33: 从业人员操作时未穿戴整洁的衣帽、口罩_环境卫生差_有白色垃圾
... A42: 41 | B42: 2021年9月3日，店铺招牌名称：寻味炸酱面，地址：浙江省杭州市西湖区，就餐场所杂物堆积，后厨灶台脏乱，垃圾桶未加盖。 | C42: =LEN(B42) -> 59 | D42: https://mp.weixin.qq.com/s?__biz=MjM5NDExMzgwNw==&mid=2651774658&idx=1&sn=e00657c3223eb6d0fb4e8ea13e1332ba&chksm=bd76cea28a0147b472704f2a1cfd675b81b7913858195193b70049c067b08f4a195b0b73df1f&scene=27 | E42: 2021年9月3日 | F42: 浙江省杭州市西湖区 | G42: 炸酱面 | H42: 寻味炸酱面 | I42: 就餐场所杂物堆积_后厨灶台脏乱_垃圾桶未加盖
A43: 42 | B43: 2022年7月4日，店铺名称：三头一掌 经营地址：浙江省杭州市西湖区，厨房环境卫生不整洁，操作台脏乱，物品摆放混乱无序，垃圾桶未加盖。 | C43: =LEN(B43) -> 67 | D43: https://mp.weixin.qq.com/s?__biz=MjM5NDExMzgwNw==&mid=2651774658&idx=1&sn=e00657c3223eb6d0fb4e8ea13e1332ba&chksm=bd76cea28a0147b472704f2a1cfd675b81b7913858195193b70049c067b08f4a195b0b73df1f&scene=27 | E43: 2022年7月4日 | F43: 浙江省杭州市西湖区 | H43: 三头一掌 | I43: 环境卫生不整洁_操作台脏乱_物品摆放混乱无序_垃圾桶未加盖
A44: 43 | B44: 2021年7月6日，店铺名称：淮南牛肉汤 地址：浙江省杭州市西湖区。上榜理由：店内后厨环境卫生较差，员工未穿戴工作衣帽，食品存储不规范。 | C44: =LEN(B44) -> 70 | D44: https://mp.weixin.qq.com/s?__biz=MjM5NDExMzgwNw==&mid=2651774658&idx=1&sn=e00657c3223eb6d0fb4e8ea13e1332ba&chksm=bd76cea28a0147b472704f2a1cfd675b81b7913858195193b70049c067b08f4a195b0b73df1f&scene=27 | E44: 2021年7月6日 | F44: 浙江省杭州市西湖区 | G44: 牛肉汤 | H44: 淮南牛肉汤 | I44: 后厨环境卫生较差_员工未穿戴工作衣帽_食品存储不规范
A45: 44 | B45: 2020年5月11日，店铺名称：桥头排骨 经营地址：浙江省杭州市西湖区，店内消毒设施未正常使用，油烟机油污严重。 | C45: =LEN(B45) -> 57 | D45: https://mp.weixin.qq.com/s?__biz=MjM5NDExMzgwNw==&mid=2651774658&idx=1&sn=e00657c3223eb6d0fb4e8ea13e1332ba&chksm=bd76cea28a0147b472704f2a1cfd675b81b7913858195193b70049c067b08f4a195b0b73df1f&scene=27 | E45: 2020年5月11日 | F45: 浙江省杭州市西湖区 | G45: 排骨 | H45: 桥头排骨 | I45: 消毒设施未正常使用_油烟机油污严重
A46: 45 | B46: 店铺招牌名称：川湘菜馆 经营地址：浙江省杭州市西湖区转塘街道博美路18号,于2022年9月4日被检查出后厨卫生脏乱，垃圾桶设置不符合要求。 | C46: =LEN(B46) -> 71 | D46: https://mp.weixin.qq.com/s?__biz=MjM5NDExMzgwNw==&mid=2651774658&idx=1&sn=e00657c3223eb6d0fb4e8ea13e1332ba&chksm=bd76cea28a0147b472704f2a1cfd675b81b7913858195193b70049c067b08f4a195b0b73df1f&scene=27 | E46: 2022年9月4日 | F46: 浙江省杭州市西湖区 | H46: 川湘菜馆 | I46: 后厨卫生脏乱_垃圾桶设置
A47: 46 | B47: 名称：杭州市滨江区金诺面馆 地址：滨江区浦沿街道，2023年5月25日被查出 后厨环境脏乱差，操作台上满是油污，地面脏，垃圾桶未加盖，缺少反浪费的宣传。 | C47: =LEN(B47) -> 78 | D47: http://www.hhtz.gov.cn/art/2023/5/25/art_1229506522_4167894.html | E47: 2023年5月25日 | F47: 杭州市滨江区 | G47: 面 | H47: 金诺面馆 | I47: 后厨环境脏乱差_操作台上满是油污_地面脏_垃圾桶未加盖
A48: 47 | B48: 名称： 杭州白金海岸美纪小吃店 地址：长河街道长河路。于2023年5月27日被记录杂物堆积，操作区墙面破损，卫生不合格，垃圾桶未加盖，操作台卫生过于脏乱。 | C48: =LEN(B48) -> 77 | D48: http://www.hhtz.gov.cn/art/2023/5/25/art_1229506522_4167894.html | E48: 2023年5月27日 | F48: 长河街道长河路 | H48: 杭州白金海岸美纪小吃店 | I48: 杂物堆积_操作区墙面破损_卫生不合格_垃圾桶未加盖_卫生过于脏乱
...
